Workbook

Sheet CHẤM VÂN TAY
A1: MÃ NV | B1: HỌ TÊN | C1: Phong ban | D1: NGÀY | E1: GIỜ BẤM TAY | F1: GIỜ VÀO | G1: GIỜ RA | H1: ĐI TRỄ | I1: VỀ SỚM | J1: CHẤM CÔNG | K1: TĂNG CA | L1: PHÉP NĂM | M1: PHỤ CẤP CƠM NGÀY CHỦ NHẬT | N1: GHI CHÚ | Q1: Check: Duyên, má 9 10/7 cúp điện
A2: 352339655 | B2: CAO THI BICH KHUONG | C2: BAC SI | D2: 46235 | E2: 08:09 19:26 | F2: =IFERROR(__xludf.DUMMYFUNCTION("MIN(ARRAYFORMULA(TIMEVALUE(SPLIT(E2,"" ""))))"),0.33958333333333335) -> 0.33958333 | G2: =IFERROR(__xludf.DUMMYFUNCTION("MAX(ARRAYFORMULA(TIMEVALUE(SPLIT(E2,"" ""))))"),0.8097222222222222) -> 0.80972222 | H2: 9 | J2: =IF(WEEKDAY(D2,2)=7,IF(AND(F2<TIME(8,15,0),G2>=TIME(11,55,0)),1,0)+IF(AND(F2<TIME(13,45,0),G2>=TIME(17,55,0)),1,0),IF(AND(F2<TIME(8,15,0),G2>=TIME(11,55,0)),1,0)+IF(AND(F2<TIME(13,45,0),G2>=TIME(17,25,0)),1,0)+IF(AND(F2<TIME(15,45,0),G2>=TIME(19,25,0)),1,0)) -> 3 | M2: =IF(WEEKDAY(D2,2)=7,IF(J2=2,1,""),"") | N2: Q7
A3: 39655 | B3: CAO THI BICH KHUONG | C3: BAC SI | D3: 46236 | E3: 07:57 07:57 18:01 18:01 18:01 | F3: =IFERROR(__xludf.DUMMYFUNCTION("MIN(ARRAYFORMULA(TIMEVALUE(SPLIT(E3,"" ""))))"),0.33125) -> 0.33125 | G3: =IFERROR(__xludf.DUMMYFUNCTION("MAX(ARRAYFORMULA(TIMEVALUE(SPLIT(E3,"" ""))))"),0.7506944444444444) -> 0.75069444 | J3: =IF(WEEKDAY(D3,2)=7,IF(AND(F3<TIME(8,15,0),G3>=TIME(11,55,0)),1,0)+IF(AND(F3<TIME(13,45,0),G3>=TIME(17,55,0)),1,0),IF(AND(F3<TIME(8,15,0),G3>=TIME(11,55,0)),1,0)+IF(AND(F3<TIME(13,45,0),G3>=TIME(17,25,0)),1,0)+IF(AND(F3<TIME(15,45,0),G3>=TIME(19,25,0)),1,0)) -> 2 | M3: =IF(WEEKDAY(D3,2)=7,IF(J3=2,1,""),"") -> 1 | O3: =CHOOSE(WEEKDAY(D3,2),"Hai","Ba","Tư","Năm","Sáu","Bảy","CN") -> CN
A4: 39655 | B4: CAO THI BICH KHUONG | C4: BAC SI | D4: 46237 | E4: 13:20 13:20 19:30 19:30 | F4: =IFERROR(__xludf.DUMMYFUNCTION("MIN(ARRAYFORMULA(TIMEVALUE(SPLIT(E4,"" ""))))"),0.5555555555555556) -> 0.55555556 | G4: =IFERROR(__xludf.DUMMYFUNCTION("MAX(ARRAYFORMULA(TIMEVALUE(SPLIT(E4,"" ""))))"),0.8125) -> 0.8125 | J4: =IF(WEEKDAY(D4,2)=7,IF(AND(F4<TIME(8,15,0),G4>=TIME(11,55,0)),1,0)+IF(AND(F4<TIME(13,45,0),G4>=TIME(17,55,0)),1,0),IF(AND(F4<TIME(8,15,0),G4>=TIME(11,55,0)),1,0)+IF(AND(F4<TIME(13,45,0),G4>=TIME(17,25,0)),1,0)+IF(AND(F4<TIME(15,45,0),G4>=TIME(19,25,0)),1,0)) -> 2 | M4: =IF(WEEKDAY(D4,2)=7,IF(J4=2,1,""),"") | O4: =CHOOSE(WEEKDAY(D4,2),"Hai","Ba","Tư","Năm","Sáu","Bảy","CN") -> Hai
A5: 39655 | B5: CAO THI BICH KHUONG | C5: BAC SI | D5: 46239 | E5: 13:27 13:27 19:31 19:31 | F5: =IFERROR(__xludf.DUMMYFUNCTION("MIN(ARRAYFORMULA(TIMEVALUE(SPLIT(E5,"" ""))))"),0.5604166666666667) -> 0.56041667 | G5: =IFERROR(__xludf.DUMMYFUNCTION("MAX(ARRAYFORMULA(TIMEVALUE(SPLIT(E5,"" ""))))"),0.8131944444444444) -> 0.81319444 | J5: =IF(WEEKDAY(D5,2)=7,IF(AND(F5<TIME(8,15,0),G5>=TIME(11,55,0)),1,0)+IF(AND(F5<TIME(13,45,0),G5>=TIME(17,55,0)),1,0),IF(AND(F5<TIME(8,15,0),G5>=TIME(11,55,0)),1,0)+IF(AND(F5<TIME(13,45,0),G5>=TIME(17,25,0)),1,0)+IF(AND(F5<TIME(15,45,0),G5>=TIME(19,25,0)),1,0)) -> 2 | M5: =IF(WEEKDAY(D5,2)=7,IF(J5=2,1,""),"") | O5: =CHOOSE(WEEKDAY(D5,2),"Hai","Ba","Tư","Năm","Sáu","Bảy","CN") -> Tư
A6: 39655 | B6: CAO THI BICH KHUONG | C6: BAC SI | D6: 46240 | E6: 07:58 07:58 19:30 | F6: =IFERROR(__xludf.DUMMYFUNCTION("MIN(ARRAYFORMULA(TIMEVALUE(SPLIT(E6,"" ""))))"),0.33194444444444443) -> 0.33194444 | G6: =IFERROR(__xludf.DUMMYFUNCTION("MAX(ARRAYFORMULA(TIMEVALUE(SPLIT(E6,"" ""))))"),0.8125) -> 0.8125 | J6: =IF(WEEKDAY(D6,2)=7,IF(AND(F6<TIME(8,15,0),G6>=TIME(11,55,0)),1,0)+IF(AND(F6<TIME(13,45,0),G6>=TIME(17,55,0)),1,0),IF(AND(F6<TIME(8,15,0),G6>=TIME(11,55,0)),1,0)+IF(AND(F6<TIME(13,45,0),G6>=TIME(17,25,0)),1,0)+IF(AND(F6<TIME(15,45,0),G6>=TIME(19,25,0)),1,0)) -> 3 | M6: =IF(WEEKDAY(D6,2)=7,IF(J6=2,1,""),"") | O6: =CHOOSE(WEEKDAY(D6,2),"Hai","Ba","Tư","Năm","Sáu","Bảy","CN") -> Năm
A7: 39655 | B7: CAO THI BICH KHUONG | C7: BAC SI | D7: 46241 | E7: 13:18 13:18 19:31 19:31 | F7: =IFERROR(__xludf.DUMMYFUNCTION("MIN(ARRAYFORMULA(TIMEVALUE(SPLIT(E7,"" ""))))"),0.5541666666666667) -> 0.55416667 | G7: =IFERROR(__xludf.DUMMYFUNCTION("MAX(ARRAYFORMULA(TIMEVALUE(SPLIT(E7,"" ""))))"),0.8131944444444444) -> 0.81319444 | J7: =IF(WEEKDAY(D7,2)=7,IF(AND(F7<TIME(8,15,0),G7>=TIME(11,55,0)),1,0)+IF(AND(F7<TIME(13,45,0),G7>=TIME(17,55,0)),1,0),IF(AND(F7<TIME(8,15,0),G7>=TIME(11,55,0)),1,0)+IF(AND(F7<TIME(13,45,0),G7>=TIME(17,25,0)),1,0)+IF(AND(F7<TIME(15,45,0),G7>=TIME(19,25,0)),1,0)) -> 2 | M7: =IF(WEEKDAY(D7,2)=7,IF(J7=2,1,""),"") | O7: =CHOOSE(WEEKDAY(D7,2),"Hai","Ba","Tư","Năm","Sáu","Bảy","CN") -> Sáu
A8: 352339655 | B8: CAO THI BICH KHUONG | C8: BAC SI | D8: 46242 | E8: 07:55 19:31 | F8: =IFERROR(__xludf.DUMMYFUNCTION("MIN(ARRAYFORMULA(TIMEVALUE(SPLIT(E8,"" ""))))"),0.3298611111111111) -> 0.32986111 | G8: =IFERROR(__xludf.DUMMYFUNCTION("MAX(ARRAYFORMULA(TIMEVALUE(SPLIT(E8,"" ""))))"),0.8131944444444444) -> 0.81319444 | J8: =IF(WEEKDAY(D8,2)=7,IF(AND(F8<TIME(8,15,0),G8>=TIME(11,55,0)),1,0)+IF(AND(F8<TIME(13,45,0),G8>=TIME(17,55,0)),1,0),IF(AND(F8<TIME(8,15,0),G8>=TIME(11,55,0)),1,0)+IF(AND(F8<TIME(13,45,0),G8>=TIME(17,25,0)),1,0)+IF(AND(F8<TIME(15,45,0),G8>=TIME(19,25,0)),1,0)) -> 3 | M8: =IF(WEEKDAY(D8,2)=7,IF(J8=2,1,""),"") | N8: Q7
A9: 39655 | B9: CAO THI BICH KHUONG | C9: BAC SI | D9: 46243 | E9: 07:55 07:55 18:00 18:00 | F9: =IFERROR(__xludf.DUMMYFUNCTION("MIN(ARRAYFORMULA(TIMEVALUE(SPLIT(E9,"" ""))))"),0.3298611111111111) -> 0.32986111 | G9: =IFERROR(__xludf.DUMMYFUNCTION("MAX(ARRAYFORMULA(TIMEVALUE(SPLIT(E9,"" ""))))"),0.75) -> 0.75 | J9: =IF(WEEKDAY(D9,2)=7,IF(AND(F9<TIME(8,15,0),G9>=TIME(11,55,0)),1,0)+IF(AND(F9<TIME(13,45,0),G9>=TIME(17,55,0)),1,0),IF(AND(F9<TIME(8,15,0),G9>=TIME(11,55,0)),1,0)+IF(AND(F9<TIME(13,45,0),G9>=TIME(17,25,0)),1,0)+IF(AND(F9<TIME(15,45,0),G9>=TIME(19,25,0)),1,0)) -> 2 | M9: =IF(WEEKDAY(D9,2)=7,IF(J9=2,1,""),"") -> 1 | O9: =CHOOSE(WEEKDAY(D9,2),"Hai","Ba","Tư","Năm","Sáu","Bảy","CN") -> CN
A10: 39655 | B10: CAO THI BICH KHUONG | C10: BAC SI | D10: 46244 | E10: 13:34 19:32 19:32 | F10: =IFERROR(__xludf.DUMMYFUNCTION("MIN(ARRAYFORMULA(TIMEVALUE(SPLIT(E10,"" ""))))"),0.5652777777777778) -> 0.56527778 | G10: =IFERROR(__xludf.DUMMYFUNCTION("MAX(ARRAYFORMULA(TIMEVALUE(SPLIT(E10,"" ""))))"),0.8138888888888889) -> 0.81388889 | J10: =IF(WEEKDAY(D10,2)=7,IF(AND(F10<TIME(8,15,0),G10>=TIME(11,55,0)),1,0)+IF(AND(F10<TIME(13,45,0),G10>=TIME(17,55,0)),1,0),IF(AND(F10<TIME(8,15,0),G10>=TIME(11,55,0)),1,0)+IF(AND(F10<TIME(13,45,0),G10>=TIME(17,25,0)),1,0)+IF(AND(F10<TIME(15,45,0),G10>=TIME(19,25,0)),1,0)) -> 2 | M10: =IF(WEEKDAY(D10,2)=7,IF(J10=2,1,""),"") | O10: =CHOOSE(WEEKDAY(D10,2),"Hai","Ba","Tư","Năm","Sáu","Bảy","CN") -> Hai
A11: 39655 | B11: CAO THI BICH KHUONG | C11: BAC SI | D11: 46248 | E11: 13:21 13:21 19:31 19:31 | F11: =IFERROR(__xludf.DUMMYFUNCTION("MIN(ARRAYFORMULA(TIMEVALUE(SPLIT(E11,"" ""))))"),0.55625) -> 0.55625 | G11: =IFERROR(__xludf.DUMMYFUNCTION("MAX(ARRAYFORMULA(TIMEVALUE(SPLIT(E11,"" ""))))"),0.8131944444444444) -> 0.81319444 | J11: =IF(WEEKDAY(D11,2)=7,IF(AND(F11<TIME(8,15,0),G11>=TIME(11,55,0)),1,0)+IF(AND(F11<TIME(13,45,0),G11>=TIME(17,55,0)),1,0),IF(AND(F11<TIME(8,15,0),G11>=TIME(11,55,0)),1,0)+IF(AND(F11<TIME(13,45,0),G11>=TIME(17,25,0)),1,0)+IF(AND(F11<TIME(15,45,0),G11>=TIME(19,25,0)),1,0)) -> 2 | M11: =IF(WEEKDAY(D11,2)=7,IF(J11=2,1,""),"") | O11: =CHOOSE(WEEKDAY(D11,2),"Hai","Ba","Tư","Năm","Sáu","Bảy","CN") -> Sáu
A12: 39655 | B12: CAO THI BICH KHUONG | C12: BAC SI | D12: 46249 | E12: 12:23 12:23 19:30 19:30 | F12: =IFERROR(__xludf.DUMMYFUNCTION("MIN(ARRAYFORMULA(TIMEVALUE(SPLIT(E12,"" ""))))"),0.5159722222222223) -> 0.51597222 | G12: =IFERROR(__xludf.DUMMYFUNCTION("MAX(ARRAYFORMULA(TIMEVALUE(SPLIT(E12,"" ""))))"),0.8125) -> 0.8125 | J12: =IF(WEEKDAY(D12,2)=7,IF(AND(F12<TIME(8,15,0),G12>=TIME(11,55,0)),1,0)+IF(AND(F12<TIME(13,45,0),G12>=TIME(17,55,0)),1,0),IF(AND(F12<TIME(8,15,0),G12>=TIME(11,55,0)),1,0)+IF(AND(F12<TIME(13,45,0),G12>=TIME(17,25,0)),1,0)+IF(AND(F12<TIME(15,45,0),G12>=TIME(19,25,0)),1,0)) -> 2 | M12: =IF(WEEKDAY(D12,2)=7,IF(J12=2,1,""),"") | O12: =CHOOSE(WEEKDAY(D12,2),"Hai","Ba","Tư","Năm","Sáu","Bảy","CN") -> Bảy
A13: 352339655 | B13: CAO THI BICH KHUONG | C13: BAC SI | D13: 46249 | E13: 07:54 12:08 | F13: =IFERROR(__xludf.DUMMYFUNCTION("MIN(ARRAYFORMULA(TIMEVALUE(SPLIT(E13,"" ""))))"),0.32916666666666666) -> 0.32916667 | G13: =IFERROR(__xludf.DUMMYFUNCTION("MAX(ARRAYFORMULA(TIMEVALUE(SPLIT(E13,"" ""))))"),0.5055555555555555) -> 0.50555556 | J13: =IF(WEEKDAY(D13,2)=7,IF(AND(F13<TIME(8,15,0),G13>=TIME(11,55,0)),1,0)+IF(AND(F13<TIME(13,45,0),G13>=TIME(17,55,0)),1,0),IF(AND(F13<TIME(8,15,0),G13>=TIME(11,55,0)),1,0)+IF(AND(F13<TIME(13,45,0),G13>=TIME(17,25,0)),1,0)+IF(AND(F13<TIME(15,45,0),G13>=TIME(19,25,0)),1,0)) -> 1 | M13: =IF(WEEKDAY(D13,2)=7,IF(J13=2,1,""),"") | N13: Q7
A14: 39655 | B14: CAO THI BICH KHUONG | C14: BAC SI | D14: 46250 | E14: 07:55 07:55 18:01 18:01 | F14: =IFERROR(__xludf.DUMMYFUNCTION("MIN(ARRAYFORMULA(TIMEVALUE(SPLIT(E14,"" ""))))"),0.3298611111111111) -> 0.32986111 | G14: =IFERROR(__xludf.DUMMYFUNCTION("MAX(ARRAYFORMULA(TIMEVALUE(SPLIT(E14,"" ""))))"),0.7506944444444444) -> 0.75069444 | J14: =IF(WEEKDAY(D14,2)=7,IF(AND(F14<TIME(8,15,0),G14>=TIME(11,55,0)),1,0)+IF(AND(F14<TIME(13,45,0),G14>=TIME(17,55,0)),1,0),IF(AND(F14<TIME(8,15,0),G14>=TIME(11,55,0)),1,0)+IF(AND(F14<TIME(13,45,0),G14>=TIME(17,25,0)),1,0)+IF(AND(F14<TIME(15,45,0),G14>=TIME(19,25,0)),1,0)) -> 2 | M14: =IF(WEEKDAY(D14,2)=7,IF(J14=2,1,""),"") -> 1 | O14: =CHOOSE(WEEKDAY(D14,2),"Hai","Ba","Tư","Năm","Sáu","Bảy","CN") -> CN
A15: 39655 | B15: CAO THI BICH KHUONG | C15: BAC SI | D15: 46251 | E15: 13:25 13:25 19:32 19:32 | F15: =IFERROR(__xludf.DUMMYFUNCTION("MIN(ARRAYFORMULA(TIMEVALUE(SPLIT(E15,"" ""))))"),0.5590277777777778) -> 0.55902778 | G15: =IFERROR(__xludf.DUMMYFUNCTION("MAX(ARRAYFORMULA(TIMEVALUE(SPLIT(E15,"" ""))))"),0.8138888888888889) -> 0.81388889 | J15: =IF(WEEKDAY(D15,2)=7,IF(AND(F15<TIME(8,15,0),G15>=TIME(11,55,0)),1,0)+IF(AND(F15<TIME(13,45,0),G15>=TIME(17,55,0)),1,0),IF(AND(F15<TIME(8,15,0),G15>=TIME(11,55,0)),1,0)+IF(AND(F15<TIME(13,45,0),G15>=TIME(17,25,0)),1,0)+IF(AND(F15<TIME(15,45,0),G15>=TIME(19,25,0)),1,0)) -> 2 | M15: =IF(WEEKDAY(D15,2)=7,IF(J15=2,1,""),"") | O15: =CHOOSE(WEEKDAY(D15,2),"Hai","Ba","Tư","Năm","Sáu","Bảy","CN") -> Hai
A16: 39655 | B16: CAO THI BICH KHUONG | C16: BAC SI | D16: 46253 | E16: 13:31 13:31 19:30 19:30 | F16: =IFERROR(__xludf.DUMMYFUNCTION("MIN(ARRAYFORMULA(TIMEVALUE(SPLIT(E16,"" ""))))"),0.5631944444444444) -> 0.56319444 | G16: =IFERROR(__xludf.DUMMYFUNCTION("MAX(ARRAYFORMULA(TIMEVALUE(SPLIT(E16,"" ""))))"),0.8125) -> 0.8125 | J16: =IF(WEEKDAY(D16,2)=7,IF(AND(F16<TIME(8,15,0),G16>=TIME(11,55,0)),1,0)+IF(AND(F16<TIME(13,45,0),G16>=TIME(17,55,0)),1,0),IF(AND(F16<TIME(8,15,0),G16>=TIME(11,55,0)),1,0)+IF(AND(F16<TIME(13,45,0),G16>=TIME(17,25,0)),1,0)+IF(AND(F16<TIME(15,45,0),G16>=TIME(19,25,0)),1,0)) -> 2 | M16: =IF(WEEKDAY(D16,2)=7,IF(J16=2,1,""),"") | O16: =CHOOSE(WEEKDAY(D16,2),"Hai","Ba","Tư","Năm","Sáu","Bảy","CN") -> Tư
A17: 352339655 | B17: CAO THI BICH KHUONG | C17: BAC SI | D17: 46254 | E17: 07:52 19:33 | F17: =IFERROR(__xludf.DUMMYFUNCTION("MIN(ARRAYFORMULA(TIMEVALUE(SPLIT(E17,"" ""))))"),0.3277777777777778) -> 0.32777778 | G17: =IFERROR(__xludf.DUMMYFUNCTION("MAX(ARRAYFORMULA(TIMEVALUE(SPLIT(E17,"" ""))))"),0.8145833333333333) -> 0.81458333 | J17: =IF(WEEKDAY(D17,2)=7,IF(AND(F17<TIME(8,15,0),G17>=TIME(11,55,0)),1,0)+IF(AND(F17<TIME(13,45,0),G17>=TIME(17,55,0)),1,0),IF(AND(F17<TIME(8,15,0),G17>=TIME(11,55,0)),1,0)+IF(AND(F17<TIME(13,45,0),G17>=TIME(17,25,0)),1,0)+IF(AND(F17<TIME(15,45,0),G17>=TIME(19,25,0)),1,0)) -> 3 | M17: =IF(WEEKDAY(D17,2)=7,IF(J17=2,1,""),"") | N17: Q7
A18: 39655 | B18: CAO THI BICH KHUONG | C18: BAC SI | D18: 46255 | E18: 13:12 13:12 19:30 19:30 | F18: =IFERROR(__xludf.DUMMYFUNCTION("MIN(ARRAYFORMULA(TIMEVALUE(SPLIT(E18,"" ""))))"),0.55) -> 0.55 | G18: =IFERROR(__xludf.DUMMYFUNCTION("MAX(ARRAYFORMULA(TIMEVALUE(SPLIT(E18,"" ""))))"),0.8125) -> 0.8125 | J18: =IF(WEEKDAY(D18,2)=7,IF(AND(F18<TIME(8,15,0),G18>=TIME(11,55,0)),1,0)+IF(AND(F18<TIME(13,45,0),G18>=TIME(17,55,0)),1,0),IF(AND(F18<TIME(8,15,0),G18>=TIME(11,55,0)),1,0)+IF(AND(F18<TIME(13,45,0),G18>=TIME(17,25,0)),1,0)+IF(AND(F18<TIME(15,45,0),G18>=TIME(19,25,0)),1,0)) -> 2 | M18: =IF(WEEKDAY(D18,2)=7,IF(J18=2,1,""),"") | O18: =CHOOSE(WEEKDAY(D18,2),"Hai","Ba","Tư","Năm","Sáu","Bảy","CN") -> Sáu
A19: 352339655 | B19: CAO THI BICH KHUONG | C19: BAC SI | D19: 46256 | E19: 07:52 19:31 | F19: =IFERROR(__xludf.DUMMYFUNCTION("MIN(ARRAYFORMULA(TIMEVALUE(SPLIT(E19,"" ""))))"),0.3277777777777778) -> 0.32777778 | G19: =IFERROR(__xludf.DUMMYFUNCTION("MAX(ARRAYFORMULA(TIMEVALUE(SPLIT(E19,"" ""))))"),0.8131944444444444) -> 0.81319444 | J19: =IF(WEEKDAY(D19,2)=7,IF(AND(F19<TIME(8,15,0),G19>=TIME(11,55,0)),1,0)+IF(AND(F19<TIME(13,45,0),G19>=TIME(17,55,0)),1,0),IF(AND(F19<TIME(8,15,0),G19>=TIME(11,55,0)),1,0)+IF(AND(F19<TIME(13,45,0),G19>=TIME(17,25,0)),1,0)+IF(AND(F19<TIME(15,45,0),G19>=TIME(19,25,0)),1,0)) -> 3 | M19: =IF(WEEKDAY(D19,2)=7,IF(J19=2,1,""),"") | N19: Q7
A20: 39655 | B20: CAO THI BICH KHUONG | C20: BAC SI | D20: 46257 | E20: 07:57 07:57 12:00 12:00 | F20: =IFERROR(__xludf.DUMMYFUNCTION("MIN(ARRAYFORMULA(TIMEVALUE(SPLIT(E20,"" ""))))"),0.33125) -> 0.33125 | G20: =IFERROR(__xludf.DUMMYFUNCTION("MAX(ARRAYFORMULA(TIMEVALUE(SPLIT(E20,"" ""))))"),0.5) -> 0.5 | J20: =IF(WEEKDAY(D20,2)=7,IF(AND(F20<TIME(8,15,0),G20>=TIME(11,55,0)),1,0)+IF(AND(F20<TIME(13,45,0),G20>=TIME(17,55,0)),1,0),IF(AND(F20<TIME(8,15,0),G20>=TIME(11,55,0)),1,0)+IF(AND(F20<TIME(13,45,0),G20>=TIME(17,25,0)),1,0)+IF(AND(F20<TIME(15,45,0),G20>=TIME(19,25,0)),1,0)) -> 1 | M20: =IF(WEEKDAY(D20,2)=7,IF(J20=2,1,""),"") | O20: =CHOOSE(WEEKDAY(D20,2),"Hai","Ba","Tư","Năm","Sáu","Bảy","CN") -> CN
A21: 39655 | B21: CAO THI BICH KHUONG | C21: BAC SI | D21: 46258 | E21: 13:21 13:21 19:32 19:32 | F21: =IFERROR(__xludf.DUMMYFUNCTION("MIN(ARRAYFORMULA(TIMEVALUE(SPLIT(E21,"" ""))))"),0.55625) -> 0.55625 | G21: =IFERROR(__xludf.DUMMYFUNCTION("MAX(ARRAYFORMULA(TIMEVALUE(SPLIT(E21,"" ""))))"),0.8138888888888889) -> 0.81388889 | J21: =IF(WEEKDAY(D21,2)=7,IF(AND(F21<TIME(8,15,0),G21>=TIME(11,55,0)),1,0)+IF(AND(F21<TIME(13,45,0),G21>=TIME(17,55,0)),1,0),IF(AND(F21<TIME(8,15,0),G21>=TIME(11,55,0)),1,0)+IF(AND(F21<TIME(13,45,0),G21>=TIME(17,25,0)),1,0)+IF(AND(F21<TIME(15,45,0),G21>=TIME(19,25,0)),1,0)) -> 2 | M21: =IF(WEEKDAY(D21,2)=7,IF(J21=2,1,""),"") | O21: =CHOOSE(WEEKDAY(D21,2),"Hai","Ba","Tư","Năm","Sáu","Bảy","CN") -> Hai
A22: 39655 | B22: CAO THI BICH KHUONG | C22: BAC SI | D22: 46260 | E22: 13:23 13:23 19:30 19:30 | F22: =IFERROR(__xludf.DUMMYFUNCTION("MIN(ARRAYFORMULA(TIMEVALUE(SPLIT(E22,"" ""))))"),0.5576388888888889) -> 0.55763889 | G22: =IFERROR(__xludf.DUMMYFUNCTION("MAX(ARRAYFORMULA(TIMEVALUE(SPLIT(E22,"" ""))))"),0.8125) -> 0.8125 | J22: =IF(WEEKDAY(D22,2)=7,IF(AND(F22<TIME(8,15,0),G22>=TIME(11,55,0)),1,0)+IF(AND(F22<TIME(13,45,0),G22>=TIME(17,55,0)),1,0),IF(AND(F22<TIME(8,15,0),G22>=TIME(11,55,0)),1,0)+IF(AND(F22<TIME(13,45,0),G22>=TIME(17,25,0)),1,0)+IF(AND(F22<TIME(15,45,0),G22>=TIME(19,25,0)),1,0)) -> 2 | M22: =IF(WEEKDAY(D22,2)=7,IF(J22=2,1,""),"") | O22: =CHOOSE(WEEKDAY(D22,2),"Hai","Ba","Tư","Năm","Sáu","Bảy","CN") -> Tư
A23: 352339655 | B23: CAO THI BICH KHUONG | C23: BAC SI | D23: 46261 | E23: 08:01 19:30 | F23: =IFERROR(__xludf.DUMMYFUNCTION("MIN(ARRAYFORMULA(TIMEVALUE(SPLIT(E23,"" ""))))"),0.33402777777777776) -> 0.33402778 | G23: =IFERROR(__xludf.DUMMYFUNCTION("MAX(ARRAYFORMULA(TIMEVALUE(SPLIT(E23,"" ""))))"),0.8125) -> 0.8125 | H23: 1 | J23: =IF(WEEKDAY(D23,2)=7,IF(AND(F23<TIME(8,15,0),G23>=TIME(11,55,0)),1,0)+IF(AND(F23<TIME(13,45,0),G23>=TIME(17,55,0)),1,0),IF(AND(F23<TIME(8,15,0),G23>=TIME(11,55,0)),1,0)+IF(AND(F23<TIME(13,45,0),G23>=TIME(17,25,0)),1,0)+IF(AND(F23<TIME(15,45,0),G23>=TIME(19,25,0)),1,0)) -> 3 | M23: =IF(WEEKDAY(D23,2)=7,IF(J23=2,1,""),"") | N23: Q1 | O23: =CHOOSE(WEEKDAY(D23,2),"Hai","Ba","Tư","Năm","Sáu","Bảy","CN") -> Năm
A24: 39655 | B24: CAO THI BICH KHUONG | C24: BAC SI | D24: 46262 | E24: 13:27 13:27 19:30 19:30 | F24: =IFERROR(__xludf.DUMMYFUNCTION("MIN(ARRAYFORMULA(TIMEVALUE(SPLIT(E24,"" ""))))"),0.5604166666666667) -> 0.56041667 | G24: =IFERROR(__xludf.DUMMYFUNCTION("MAX(ARRAYFORMULA(TIMEVALUE(SPLIT(E24,"" ""))))"),0.8125) -> 0.8125 | J24: =IF(WEEKDAY(D24,2)=7,IF(AND(F24<TIME(8,15,0),G24>=TIME(11,55,0)),1,0)+IF(AND(F24<TIME(13,45,0),G24>=TIME(17,55,0)),1,0),IF(AND(F24<TIME(8,15,0),G24>=TIME(11,55,0)),1,0)+IF(AND(F24<TIME(13,45,0),G24>=TIME(17,25,0)),1,0)+IF(AND(F24<TIME(15,45,0),G24>=TIME(19,25,0)),1,0)) -> 2 | M24: =IF(WEEKDAY(D24,2)=7,IF(J24=2,1,""),"") | O24: =CHOOSE(WEEKDAY(D24,2),"Hai","Ba","Tư","Năm","Sáu","Bảy","CN") -> Sáu
A25: 39655 | B25: CAO THI BICH KHUONG | C25: BAC SI | D25: 46263 | E25: 07:55 07:55 19:31 19:31 | F25: =IFERROR(__xludf.DUMMYFUNCTION("MIN(ARRAYFORMULA(TIMEVALUE(SPLIT(E25,"" ""))))"),0.3298611111111111) -> 0.32986111 | G25: =IFERROR(__xludf.DUMMYFUNCTION("MAX(ARRAYFORMULA(TIMEVALUE(SPLIT(E25,"" ""))))"),0.8131944444444444) -> 0.81319444 | J25: =IF(WEEKDAY(D25,2)=7,IF(AND(F25<TIME(8,15,0),G25>=TIME(11,55,0)),1,0)+IF(AND(F25<TIME(13,45,0),G25>=TIME(17,55,0)),1,0),IF(AND(F25<TIME(8,15,0),G25>=TIME(11,55,0)),1,0)+IF(AND(F25<TIME(13,45,0),G25>=TIME(17,25,0)),1,0)+IF(AND(F25<TIME(15,45,0),G25>=TIME(19,25,0)),1,0)) -> 3 | M25: =IF(WEEKDAY(D25,2)=7,IF(J25=2,1,""),"") | O25: =CHOOSE(WEEKDAY(D25,2),"Hai","Ba","Tư","Năm","Sáu","Bảy","CN") -> Bảy
A26: 39655 | B26: CAO THI BICH KHUONG | C26: BAC SI | D26: 46264 | E26: 07:56 07:56 18:00 18:00 | F26: =IFERROR(__xludf.DUMMYFUNCTION("MIN(ARRAYFORMULA(TIMEVALUE(SPLIT(E26,"" ""))))"),0.33055555555555555) -> 0.33055556 | G26: =IFERROR(__xludf.DUMMYFUNCTION("MAX(ARRAYFORMULA(TIMEVALUE(SPLIT(E26,"" ""))))"),0.75) -> 0.75 | J26: =IF(WEEKDAY(D26,2)=7,IF(AND(F26<TIME(8,15,0),G26>=TIME(11,55,0)),1,0)+IF(AND(F26<TIME(13,45,0),G26>=TIME(17,55,0)),1,0),IF(AND(F26<TIME(8,15,0),G26>=TIME(11,55,0)),1,0)+IF(AND(F26<TIME(13,45,0),G26>=TIME(17,25,0)),1,0)+IF(AND(F26<TIME(15,45,0),G26>=TIME(19,25,0)),1,0)) -> 2 | M26: =IF(WEEKDAY(D26,2)=7,IF(J26=2,1,""),"") -> 1 | O26: =CHOOSE(WEEKDAY(D26,2),"Hai","Ba","Tư","Năm","Sáu","Bảy","CN") -> CN
A27: 39655 | B27: CAO THI BICH KHUONG | C27: BAC SI | D27: 46265 | E27: 13:34 19:30 19:30 | F27: =IFERROR(__xludf.DUMMYFUNCTION("MIN(ARRAYFORMULA(TIMEVALUE(SPLIT(E27,"" ""))))"),0.5652777777777778) -> 0.56527778 | G27: =IFERROR(__xludf.DUMMYFUNCTION("MAX(ARRAYFORMULA(TIMEVALUE(SPLIT(E27,"" ""))))"),0.8125) -> 0.8125 | J27: =IF(WEEKDAY(D27,2)=7,IF(AND(F27<TIME(8,15,0),G27>=TIME(11,55,0)),1,0)+IF(AND(F27<TIME(13,45,0),G27>=TIME(17,55,0)),1,0),IF(AND(F27<TIME(8,15,0),G27>=TIME(11,55,0)),1,0)+IF(AND(F27<TIME(13,45,0),G27>=TIME(17,25,0)),1,0)+IF(AND(F27<TIME(15,45,0),G27>=TIME(19,25,0)),1,0)) -> 2 | M27: =IF(WEEKDAY(D27,2)=7,IF(J27=2,1,""),"") | O27: =CHOOSE(WEEKDAY(D27,2),"Hai","Ba","Tư","Năm","Sáu","Bảy","CN") -> Hai
A28: 74798 | B28: DO PHU DUC | C28: BAC SI | D28: 46235 | E28: 08:22 19:30 | F28: =IFERROR(__xludf.DUMMYFUNCTION("MIN(ARRAYFORMULA(TIMEVALUE(SPLIT(E28,"" ""))))"),0.3486111111111111) -> 0.34861111 | G28: =IFERROR(__xludf.DUMMYFUNCTION("MAX(ARRAYFORMULA(TIMEVALUE(SPLIT(E28,"" ""))))"),0.8125) -> 0.8125 | H28: 22 | J28: =IF(WEEKDAY(D28,2)=7,IF(AND(F28<TIME(8,15,0),G28>=TIME(11,55,0)),1,0)+IF(AND(F28<TIME(13,45,0),G28>=TIME(17,55,0)),1,0),IF(AND(F28<TIME(8,15,0),G28>=TIME(11,55,0)),1,0)+IF(AND(F28<TIME(13,45,0),G28>=TIME(17,25,0)),1,0)+IF(AND(F28<TIME(15,45,0),G28>=TIME(19,25,0)),1,0)) -> 2 | M28: =IF(WEEKDAY(D28,2)=7,IF(J28=2,1,""),"") | O28: =CHOOSE(WEEKDAY(D28,2),"Hai","Ba","Tư","Năm","Sáu","Bảy","CN") -> Bảy
A29: 74798 | B29: DO PHU DUC | C29: BAC SI | D29: 46236 | E29: 07:53 18:12 | F29: =IFERROR(__xludf.DUMMYFUNCTION("MIN(ARRAYFORMULA(TIMEVALUE(SPLIT(E29,"" ""))))"),0.3284722222222222) -> 0.32847222 | G29: =IFERROR(__xludf.DUMMYFUNCTION("MAX(ARRAYFORMULA(TIMEVALUE(SPLIT(E29,"" ""))))"),0.7583333333333333) -> 0.75833333 | J29: =IF(WEEKDAY(D29,2)=7,IF(AND(F29<TIME(8,15,0),G29>=TIME(11,55,0)),1,0)+IF(AND(F29<TIME(13,45,0),G29>=TIME(17,55,0)),1,0),IF(AND(F29<TIME(8,15,0),G29>=TIME(11,55,0)),1,0)+IF(AND(F29<TIME(13,45,0),G29>=TIME(17,25,0)),1,0)+IF(AND(F29<TIME(15,45,0),G29>=TIME(19,25,0)),1,0)) -> 2 | M29: =IF(WEEKDAY(D29,2)=7,IF(J29=2,1,""),"") -> 1 | O29: =CHOOSE(WEEKDAY(D29,2),"Hai","Ba","Tư","Năm","Sáu","Bảy","CN") -> CN
A30: 74798 | B30: DO PHU DUC | C30: BAC SI | D30: 46237 | E30: 07:58 19:30 | F30: =IFERROR(__xludf.DUMMYFUNCTION("MIN(ARRAYFORMULA(TIMEVALUE(SPLIT(E30,"" ""))))"),0.33194444444444443) -> 0.33194444 | G30: =IFERROR(__xludf.DUMMYFUNCTION("MAX(ARRAYFORMULA(TIMEVALUE(SPLIT(E30,"" ""))))"),0.8125) -> 0.8125 | J30: =IF(WEEKDAY(D30,2)=7,IF(AND(F30<TIME(8,15,0),G30>=TIME(11,55,0)),1,0)+IF(AND(F30<TIME(13,45,0),G30>=TIME(17,55,0)),1,0),IF(AND(F30<TIME(8,15,0),G30>=TIME(11,55,0)),1,0)+IF(AND(F30<TIME(13,45,0),G30>=TIME(17,25,0)),1,0)+IF(AND(F30<TIME(15,45,0),G30>=TIME(19,25,0)),1,0)) -> 3 | M30: =IF(WEEKDAY(D30,2)=7,IF(J30=2,1,""),"") | O30: =CHOOSE(WEEKDAY(D30,2),"Hai","Ba","Tư","Năm","Sáu","Bảy","CN") -> Hai
A31: 74798 | B31: DO PHU DUC | C31: BAC SI | D31: 46239 | E31: 07:56 19:30 | F31: =IFERROR(__xludf.DUMMYFUNCTION("MIN(ARRAYFORMULA(TIMEVALUE(SPLIT(E31,"" ""))))"),0.33055555555555555) -> 0.33055556 | G31: =IFERROR(__xludf.DUMMYFUNCTION("MAX(ARRAYFORMULA(TIMEVALUE(SPLIT(E31,"" ""))))"),0.8125) -> 0.8125 | J31: =IF(WEEKDAY(D31,2)=7,IF(AND(F31<TIME(8,15,0),G31>=TIME(11,55,0)),1,0)+IF(AND(F31<TIME(13,45,0),G31>=TIME(17,55,0)),1,0),IF(AND(F31<TIME(8,15,0),G31>=TIME(11,55,0)),1,0)+IF(AND(F31<TIME(13,45,0),G31>=TIME(17,25,0)),1,0)+IF(AND(F31<TIME(15,45,0),G31>=TIME(19,25,0)),1,0)) -> 3 | M31: =IF(WEEKDAY(D31,2)=7,IF(J31=2,1,""),"") | O31: =CHOOSE(WEEKDAY(D31,2),"Hai","Ba","Tư","Năm","Sáu","Bảy","CN") -> Tư
A32: 74798 | B32: DO PHU DUC | C32: BAC SI | D32: 46240 | E32: 08:00 19:30 | F32: =IFERROR(__xludf.DUMMYFUNCTION("MIN(ARRAYFORMULA(TIMEVALUE(SPLIT(E32,"" ""))))"),0.3333333333333333) -> 0.33333333 | G32: =IFERROR(__xludf.DUMMYFUNCTION("MAX(ARRAYFORMULA(TIMEVALUE(SPLIT(E32,"" ""))))"),0.8125) -> 0.8125 | J32: =IF(WEEKDAY(D32,2)=7,IF(AND(F32<TIME(8,15,0),G32>=TIME(11,55,0)),1,0)+IF(AND(F32<TIME(13,45,0),G32>=TIME(17,55,0)),1,0),IF(AND(F32<TIME(8,15,0),G32>=TIME(11,55,0)),1,0)+IF(AND(F32<TIME(13,45,0),G32>=TIME(17,25,0)),1,0)+IF(AND(F32<TIME(15,45,0),G32>=TIME(19,25,0)),1,0)) -> 3 | M32: =IF(WEEKDAY(D32,2)=7,IF(J32=2,1,""),"") | O32: =CHOOSE(WEEKDAY(D32,2),"Hai","Ba","Tư","Năm","Sáu","Bảy","CN") -> Năm
A33: 74798 | B33: DO PHU DUC | C33: BAC SI | D33: 46241 | E33: 08:05 19:31 | F33: =IFERROR(__xludf.DUMMYFUNCTION("MIN(ARRAYFORMULA(TIMEVALUE(SPLIT(E33,"" ""))))"),0.3368055555555556) -> 0.33680556 | G33: =IFERROR(__xludf.DUMMYFUNCTION("MAX(ARRAYFORMULA(TIMEVALUE(SPLIT(E33,"" ""))))"),0.8131944444444444) -> 0.81319444 | H33: 5 | J33: =IF(WEEKDAY(D33,2)=7,IF(AND(F33<TIME(8,15,0),G33>=TIME(11,55,0)),1,0)+IF(AND(F33<TIME(13,45,0),G33>=TIME(17,55,0)),1,0),IF(AND(F33<TIME(8,15,0),G33>=TIME(11,55,0)),1,0)+IF(AND(F33<TIME(13,45,0),G33>=TIME(17,25,0)),1,0)+IF(AND(F33<TIME(15,45,0),G33>=TIME(19,25,0)),1,0)) -> 3 | M33: =IF(WEEKDAY(D33,2)=7,IF(J33=2,1,""),"") | O33: =CHOOSE(WEEKDAY(D33,2),"Hai","Ba","Tư","Năm","Sáu","Bảy","CN") -> Sáu
A34: 74798 | B34: DO PHU DUC | C34: BAC SI | D34: 46243 | E34: 07:55 18:00 | F34: =IFERROR(__xludf.DUMMYFUNCTION("MIN(ARRAYFORMULA(TIMEVALUE(SPLIT(E34,"" ""))))"),0.3298611111111111) -> 0.32986111 | G34: =IFERROR(__xludf.DUMMYFUNCTION("MAX(ARRAYFORMULA(TIMEVALUE(SPLIT(E34,"" ""))))"),0.75) -> 0.75 | J34: =IF(WEEKDAY(D34,2)=7,IF(AND(F34<TIME(8,15,0),G34>=TIME(11,55,0)),1,0)+IF(AND(F34<TIME(13,45,0),G34>=TIME(17,55,0)),1,0),IF(AND(F34<TIME(8,15,0),G34>=TIME(11,55,0)),1,0)+IF(AND(F34<TIME(13,45,0),G34>=TIME(17,25,0)),1,0)+IF(AND(F34<TIME(15,45,0),G34>=TIME(19,25,0)),1,0)) -> 2 | M34: =IF(WEEKDAY(D34,2)=7,IF(J34=2,1,""),"") -> 1 | O34: =CHOOSE(WEEKDAY(D34,2),"Hai","Ba","Tư","Năm","Sáu","Bảy","CN") -> CN
A35: 74798 | B35: DO PHU DUC | C35: BAC SI | D35: 46244 | E35: 08:05 19:30 | F35: =IFERROR(__xludf.DUMMYFUNCTION("MIN(ARRAYFORMULA(TIMEVALUE(SPLIT(E35,"" ""))))"),0.3368055555555556) -> 0.33680556 | G35: =IFERROR(__xludf.DUMMYFUNCTION("MAX(ARRAYFORMULA(TIMEVALUE(SPLIT(E35,"" ""))))"),0.8125) -> 0.8125 | H35: 5 | J35: =IF(WEEKDAY(D35,2)=7,IF(AND(F35<TIME(8,15,0),G35>=TIME(11,55,0)),1,0)+IF(AND(F35<TIME(13,45,0),G35>=TIME(17,55,0)),1,0),IF(AND(F35<TIME(8,15,0),G35>=TIME(11,55,0)),1,0)+IF(AND(F35<TIME(13,45,0),G35>=TIME(17,25,0)),1,0)+IF(AND(F35<TIME(15,45,0),G35>=TIME(19,25,0)),1,0)) -> 3 | M35: =IF(WEEKDAY(D35,2)=7,IF(J35=2,1,""),"") | O35: =CHOOSE(WEEKDAY(D35,2),"Hai","Ba","Tư","Năm","Sáu","Bảy","CN") -> Hai
A36: 74798 | B36: DO PHU DUC | C36: BAC SI | D36: 46248 | E36: 08:07 19:30 | F36: =IFERROR(__xludf.DUMMYFUNCTION("MIN(ARRAYFORMULA(TIMEVALUE(SPLIT(E36,"" ""))))"),0.33819444444444446) -> 0.33819444 | G36: =IFERROR(__xludf.DUMMYFUNCTION("MAX(ARRAYFORMULA(TIMEVALUE(SPLIT(E36,"" ""))))"),0.8125) -> 0.8125 | H36: 7 | J36: =IF(WEEKDAY(D36,2)=7,IF(AND(F36<TIME(8,15,0),G36>=TIME(11,55,0)),1,0)+IF(AND(F36<TIME(13,45,0),G36>=TIME(17,55,0)),1,0),IF(AND(F36<TIME(8,15,0),G36>=TIME(11,55,0)),1,0)+IF(AND(F36<TIME(13,45,0),G36>=TIME(17,25,0)),1,0)+IF(AND(F36<TIME(15,45,0),G36>=TIME(19,25,0)),1,0)) -> 3 | M36: =IF(WEEKDAY(D36,2)=7,IF(J36=2,1,""),"") | O36: =CHOOSE(WEEKDAY(D36,2),"Hai","Ba","Tư","Năm","Sáu","Bảy","CN") -> Sáu
A37: 74798 | B37: DO PHU DUC | C37: BAC SI | D37: 46249 | E37: 07:59 19:30 | F37: =IFERROR(__xludf.DUMMYFUNCTION("MIN(ARRAYFORMULA(TIMEVALUE(SPLIT(E37,"" ""))))"),0.3326388888888889) -> 0.33263889 | G37: =IFERROR(__xludf.DUMMYFUNCTION("MAX(ARRAYFORMULA(TIMEVALUE(SPLIT(E37,"" ""))))"),0.8125) -> 0.8125 | J37: =IF(WEEKDAY(D37,2)=7,IF(AND(F37<TIME(8,15,0),G37>=TIME(11,55,0)),1,0)+IF(AND(F37<TIME(13,45,0),G37>=TIME(17,55,0)),1,0),IF(AND(F37<TIME(8,15,0),G37>=TIME(11,55,0)),1,0)+IF(AND(F37<TIME(13,45,0),G37>=TIME(17,25,0)),1,0)+IF(AND(F37<TIME(15,45,0),G37>=TIME(19,25,0)),1,0)) -> 3 | M37: =IF(WEEKDAY(D37,2)=7,IF(J37=2,1,""),"") | O37: =CHOOSE(WEEKDAY(D37,2),"Hai","Ba","Tư","Năm","Sáu","Bảy","CN") -> Bảy
A38: 74798 | B38: DO PHU DUC | C38: BAC SI | D38: 46250 | E38: 08:05 18:01 | F38: =IFERROR(__xludf.DUMMYFUNCTION("MIN(ARRAYFORMULA(TIMEVALUE(SPLIT(E38,"" ""))))"),0.3368055555555556) -> 0.33680556 | G38: =IFERROR(__xludf.DUMMYFUNCTION("MAX(ARRAYFORMULA(TIMEVALUE(SPLIT(E38,"" ""))))"),0.7506944444444444) -> 0.75069444 | H38: 5 | J38: =IF(WEEKDAY(D38,2)=7,IF(AND(F38<TIME(8,15,0),G38>=TIME(11,55,0)),1,0)+IF(AND(F38<TIME(13,45,0),G38>=TIME(17,55,0)),1,0),IF(AND(F38<TIME(8,15,0),G38>=TIME(11,55,0)),1,0)+IF(AND(F38<TIME(13,45,0),G38>=TIME(17,25,0)),1,0)+IF(AND(F38<TIME(15,45,0),G38>=TIME(19,25,0)),1,0)) -> 2 | M38: =IF(WEEKDAY(D38,2)=7,IF(J38=2,1,""),"") -> 1 | O38: =CHOOSE(WEEKDAY(D38,2),"Hai","Ba","Tư","Năm","Sáu","Bảy","CN") -> CN
A39: 74798 | B39: DO PHU DUC | C39: BAC SI | D39: 46251 | E39: 08:00 19:36 | F39: =IFERROR(__xludf.DUMMYFUNCTION("MIN(ARRAYFORMULA(TIMEVALUE(SPLIT(E39,"" ""))))"),0.3333333333333333) -> 0.33333333 | G39: =IFERROR(__xludf.DUMMYFUNCTION("MAX(ARRAYFORMULA(TIMEVALUE(SPLIT(E39,"" ""))))"),0.8166666666666667) -> 0.81666667 | J39: =IF(WEEKDAY(D39,2)=7,IF(AND(F39<TIME(8,15,0),G39>=TIME(11,55,0)),1,0)+IF(AND(F39<TIME(13,45,0),G39>=TIME(17,55,0)),1,0),IF(AND(F39<TIME(8,15,0),G39>=TIME(11,55,0)),1,0)+IF(AND(F39<TIME(13,45,0),G39>=TIME(17,25,0)),1,0)+IF(AND(F39<TIME(15,45,0),G39>=TIME(19,25,0)),1,0)) -> 3 | M39: =IF(WEEKDAY(D39,2)=7,IF(J39=2,1,""),"") | O39: =CHOOSE(WEEKDAY(D39,2),"Hai","Ba","Tư","Năm","Sáu","Bảy","CN") -> Hai
A40: 74798 | B40: DO PHU DUC | C40: BAC SI | D40: 46252 | E40: 07:55 19:30 | F40: =IFERROR(__xludf.DUMMYFUNCTION("MIN(ARRAYFORMULA(TIMEVALUE(SPLIT(E40,"" ""))))"),0.3298611111111111) -> 0.32986111 | G40: =IFERROR(__xludf.DUMMYFUNCTION("MAX(ARRAYFORMULA(TIMEVALUE(SPLIT(E40,"" ""))))"),0.8125) -> 0.8125 | J40: =IF(WEEKDAY(D40,2)=7,IF(AND(F40<TIME(8,15,0),G40>=TIME(11,55,0)),1,0)+IF(AND(F40<TIME(13,45,0),G40>=TIME(17,55,0)),1,0),IF(AND(F40<TIME(8,15,0),G40>=TIME(11,55,0)),1,0)+IF(AND(F40<TIME(13,45,0),G40>=TIME(17,25,0)),1,0)+IF(AND(F40<TIME(15,45,0),G40>=TIME(19,25,0)),1,0)) -> 3 | M40: =IF(WEEKDAY(D40,2)=7,IF(J40=2,1,""),"") | O40: =CHOOSE(WEEKDAY(D40,2),"Hai","Ba","Tư","Năm","Sáu","Bảy","CN") -> Ba
...

Sheet TỔNG HỢP
A1: T8/2026 THỐNG KÊ CHẤM CÔNG NHÂN SỰ QUẬN 1 | D1: TỔNG
A2: STT | B2: Ten | C2: Phong ban | D2: ĐI TRỄ | E2: VỀ SỚM | F2: CHẤM CÔNG | G2: TĂNG CA | H2: PHÉP NĂM | I2: SỐ NGÀY NHẬN PHỤ CẤP CƠM CHỦ NHẬT | J2: GHI CHÚ
A3: 1 | B3: BUI THI MY LINH | C3: BAC SI | D3: =sumif('CHẤM VÂN TAY'!B:B,B3,'CHẤM VÂN TAY'!H:H) -> 0 | E3: =SUMIF('CHẤM VÂN TAY'!B:B,B3,'CHẤM VÂN TAY'!I:I) -> 0 | F3: =SUMIF('CHẤM VÂN TAY'!B:B,B3,'CHẤM VÂN TAY'!J:J) -> 0 | G3: =SUMIF('CHẤM VÂN TAY'!B:B,B3,'CHẤM VÂN TAY'!K:K) -> 0 | H3: =SUMIF('CHẤM VÂN TAY'!B:B,B3,'CHẤM VÂN TAY'!L:L) -> 0 | I3: =SUMIF('CHẤM VÂN TAY'!B:B,B3,'CHẤM VÂN TAY'!M:M) -> 0 | J3: Sử dụng 8 ca phép năm
A4: 2 | B4: PHAN THI UYEN THUY | C4: BAC SI | D4: =sumif('CHẤM VÂN TAY'!B:B,B4,'CHẤM VÂN TAY'!H:H) -> 17 | E4: =SUMIF('CHẤM VÂN TAY'!B:B,B4,'CHẤM VÂN TAY'!I:I) -> 0 | F4: =SUMIF('CHẤM VÂN TAY'!B:B,B4,'CHẤM VÂN TAY'!J:J) -> 57 | G4: =SUMIF('CHẤM VÂN TAY'!B:B,B4,'CHẤM VÂN TAY'!K:K) -> 0 | H4: =SUMIF('CHẤM VÂN TAY'!B:B,B4,'CHẤM VÂN TAY'!L:L) -> 1 | I4: =SUMIF('CHẤM VÂN TAY'!B:B,B4,'CHẤM VÂN TAY'!M:M) -> 1
A5: 3 | B5: NGUYEN MINH HANG | C5: BAC SI | D5: =sumif('CHẤM VÂN TAY'!B:B,B5,'CHẤM VÂN TAY'!H:H) -> 2 | E5: =SUMIF('CHẤM VÂN TAY'!B:B,B5,'CHẤM VÂN TAY'!I:I) -> 0 | F5: =SUMIF('CHẤM VÂN TAY'!B:B,B5,'CHẤM VÂN TAY'!J:J) -> 62 | G5: =SUMIF('CHẤM VÂN TAY'!B:B,B5,'CHẤM VÂN TAY'!K:K) -> 0 | H5: =SUMIF('CHẤM VÂN TAY'!B:B,B5,'CHẤM VÂN TAY'!L:L) -> 3 | I5: =SUMIF('CHẤM VÂN TAY'!B:B,B5,'CHẤM VÂN TAY'!M:M) -> 3
A6: 4 | B6: DO PHU DUC | C6: BAC SI | D6: =sumif('CHẤM VÂN TAY'!B:B,B6,'CHẤM VÂN TAY'!H:H) -> 98 | E6: =SUMIF('CHẤM VÂN TAY'!B:B,B6,'CHẤM VÂN TAY'!I:I) -> 0 | F6: =SUMIF('CHẤM VÂN TAY'!B:B,B6,'CHẤM VÂN TAY'!J:J) -> 65 | G6: =SUMIF('CHẤM VÂN TAY'!B:B,B6,'CHẤM VÂN TAY'!K:K) -> 0 | H6: =SUMIF('CHẤM VÂN TAY'!B:B,B6,'CHẤM VÂN TAY'!L:L) -> 0 | I6: =SUMIF('CHẤM VÂN TAY'!B:B,B6,'CHẤM VÂN TAY'!M:M) -> 4
A7: 5 | B7: TRAN DUC TOAN | C7: BAC SI | D7: =sumif('CHẤM VÂN TAY'!B:B,B7,'CHẤM VÂN TAY'!H:H) -> 76 | E7: =SUMIF('CHẤM VÂN TAY'!B:B,B7,'CHẤM VÂN TAY'!I:I) -> 0 | F7: =SUMIF('CHẤM VÂN TAY'!B:B,B7,'CHẤM VÂN TAY'!J:J) -> 69 | G7: =SUMIF('CHẤM VÂN TAY'!B:B,B7,'CHẤM VÂN TAY'!K:K) -> 0 | H7: =SUMIF('CHẤM VÂN TAY'!B:B,B7,'CHẤM VÂN TAY'!L:L) -> 0 | I7: =SUMIF('CHẤM VÂN TAY'!B:B,B7,'CHẤM VÂN TAY'!M:M) -> 4
A8: 6 | B8: NGUYEN QUOC TUAN | C8: BAC SI | D8: =sumif('CHẤM VÂN TAY'!B:B,B8,'CHẤM VÂN TAY'!H:H) -> 0 | E8: =SUMIF('CHẤM VÂN TAY'!B:B,B8,'CHẤM VÂN TAY'!I:I) -> 0 | F8: =SUMIF('CHẤM VÂN TAY'!B:B,B8,'CHẤM VÂN TAY'!J:J) -> 29 | G8: =SUMIF('CHẤM VÂN TAY'!B:B,B8,'CHẤM VÂN TAY'!K:K) -> 0 | H8: =SUMIF('CHẤM VÂN TAY'!B:B,B8,'CHẤM VÂN TAY'!L:L) -> 0 | I8: =SUMIF('CHẤM VÂN TAY'!B:B,B8,'CHẤM VÂN TAY'!M:M) -> 0
A9: 7 | B9: NGUYEN TRAN THANH TH | C9: BAC SI | D9: =sumif('CHẤM VÂN TAY'!B:B,B9,'CHẤM VÂN TAY'!H:H) -> 0 | E9: =SUMIF('CHẤM VÂN TAY'!B:B,B9,'CHẤM VÂN TAY'!I:I) -> 0 | F9: =SUMIF('CHẤM VÂN TAY'!B:B,B9,'CHẤM VÂN TAY'!J:J) -> 27 | G9: =SUMIF('CHẤM VÂN TAY'!B:B,B9,'CHẤM VÂN TAY'!K:K) -> 0 | H9: =SUMIF('CHẤM VÂN TAY'!B:B,B9,'CHẤM VÂN TAY'!L:L) -> 0 | I9: =SUMIF('CHẤM VÂN TAY'!B:B,B9,'CHẤM VÂN TAY'!M:M) -> 0
A10: 8 | B10: NGO HOANG DUY | C10: IT | D10: =sumif('CHẤM VÂN TAY'!B:B,B10,'CHẤM VÂN TAY'!H:H) -> 1 | E10: =SUMIF('CHẤM VÂN TAY'!B:B,B10,'CHẤM VÂN TAY'!I:I) -> 0 | F10: =SUMIF('CHẤM VÂN TAY'!B:B,B10,'CHẤM VÂN TAY'!J:J) -> 12 | G10: =SUMIF('CHẤM VÂN TAY'!B:B,B10,'CHẤM VÂN TAY'!K:K) -> 0 | H10: =SUMIF('CHẤM VÂN TAY'!B:B,B10,'CHẤM VÂN TAY'!L:L) -> 0 | I10: =SUMIF('CHẤM VÂN TAY'!B:B,B10,'CHẤM VÂN TAY'!M:M) -> 0
A11: 9 | B11: NGUYEN NGA UYEN CHI | C11: LE TAN | D11: =sumif('CHẤM VÂN TAY'!B:B,B11,'CHẤM VÂN TAY'!H:H) -> 1 | E11: =SUMIF('CHẤM VÂN TAY'!B:B,B11,'CHẤM VÂN TAY'!I:I) -> 0 | F11: =SUMIF('CHẤM VÂN TAY'!B:B,B11,'CHẤM VÂN TAY'!J:J) -> 60 | G11: =SUMIF('CHẤM VÂN TAY'!B:B,B11,'CHẤM VÂN TAY'!K:K) -> 0 | H11: =SUMIF('CHẤM VÂN TAY'!B:B,B11,'CHẤM VÂN TAY'!L:L) -> 2 | I11: =SUMIF('CHẤM VÂN TAY'!B:B,B11,'CHẤM VÂN TAY'!M:M) -> 2
A12: 10 | B12: HO HOANG HAI | C12: LE TAN | D12: =sumif('CHẤM VÂN TAY'!B:B,B12,'CHẤM VÂN TAY'!H:H) -> 6 | E12: =SUMIF('CHẤM VÂN TAY'!B:B,B12,'CHẤM VÂN TAY'!I:I) -> 0 | F12: =SUMIF('CHẤM VÂN TAY'!B:B,B12,'CHẤM VÂN TAY'!J:J) -> 64 | G12: =SUMIF('CHẤM VÂN TAY'!B:B,B12,'CHẤM VÂN TAY'!K:K) -> 15 | H12: =SUMIF('CHẤM VÂN TAY'!B:B,B12,'CHẤM VÂN TAY'!L:L) -> 0 | I12: =SUMIF('CHẤM VÂN TAY'!B:B,B12,'CHẤM VÂN TAY'!M:M) -> 1
A13: 11 | B13: LE NGUYEN TRAM ANH | C13: LE TAN | D13: =sumif('CHẤM VÂN TAY'!B:B,B13,'CHẤM VÂN TAY'!H:H) -> 0 | E13: =SUMIF('CHẤM VÂN TAY'!B:B,B13,'CHẤM VÂN TAY'!I:I) -> 0 | F13: =SUMIF('CHẤM VÂN TAY'!B:B,B13,'CHẤM VÂN TAY'!J:J) -> 58 | G13: =SUMIF('CHẤM VÂN TAY'!B:B,B13,'CHẤM VÂN TAY'!K:K) -> 0 | H13: =SUMIF('CHẤM VÂN TAY'!B:B,B13,'CHẤM VÂN TAY'!L:L) -> 5 | I13: =SUMIF('CHẤM VÂN TAY'!B:B,B13,'CHẤM VÂN TAY'!M:M) -> 1
A14: 12 | B14: CAO THI BICH KHUONG | C14: BAC SI | D14: =sumif('CHẤM VÂN TAY'!B:B,B14,'CHẤM VÂN TAY'!H:H) -> 10 | E14: =SUMIF('CHẤM VÂN TAY'!B:B,B14,'CHẤM VÂN TAY'!I:I) -> 0 | F14: =SUMIF('CHẤM VÂN TAY'!B:B,B14,'CHẤM VÂN TAY'!J:J) -> 57 | G14: =SUMIF('CHẤM VÂN TAY'!B:B,B14,'CHẤM VÂN TAY'!K:K) -> 0 | H14: =SUMIF('CHẤM VÂN TAY'!B:B,B14,'CHẤM VÂN TAY'!L:L) -> 0 | I14: =SUMIF('CHẤM VÂN TAY'!B:B,B14,'CHẤM VÂN TAY'!M:M) -> 4
A15: 13 | B15: NGUYEN THI MY NUONG | C15: BAC SI | D15: =sumif('CHẤM VÂN TAY'!B:B,B15,'CHẤM VÂN TAY'!H:H) -> 1 | E15: =SUMIF('CHẤM VÂN TAY'!B:B,B15,'CHẤM VÂN TAY'!I:I) -> 0 | F15: =SUMIF('CHẤM VÂN TAY'!B:B,B15,'CHẤM VÂN TAY'!J:J) -> 63 | G15: =SUMIF('CHẤM VÂN TAY'!B:B,B15,'CHẤM VÂN TAY'!K:K) -> 0 | H15: =SUMIF('CHẤM VÂN TAY'!B:B,B15,'CHẤM VÂN TAY'!L:L) -> 0 | I15: =SUMIF('CHẤM VÂN TAY'!B:B,B15,'CHẤM VÂN TAY'!M:M) -> 1
... A22: 21 | B22: TRUONG THI TOC | C22: TAP VU | D22: =sumif('CHẤM VÂN TAY'!B:B,B22,'CHẤM VÂN TAY'!H:H) -> 0 | E22: =SUMIF('CHẤM VÂN TAY'!B:B,B22,'CHẤM VÂN TAY'!I:I) -> 0 | F22: =SUMIF('CHẤM VÂN TAY'!B:B,B22,'CHẤM VÂN TAY'!J:J) -> 53 | G22: =SUMIF('CHẤM VÂN TAY'!B:B,B22,'CHẤM VÂN TAY'!K:K) -> 0 | H22: =SUMIF('CHẤM VÂN TAY'!B:B,B22,'CHẤM VÂN TAY'!L:L) -> 0 | I22: =SUMIF('CHẤM VÂN TAY'!B:B,B22,'CHẤM VÂN TAY'!M:M) -> 0
A23: 22 | B23: HUYNH PHI LONG | C23: VO TRUNG | D23: =sumif('CHẤM VÂN TAY'!B:B,B23,'CHẤM VÂN TAY'!H:H) -> 13 | E23: =SUMIF('CHẤM VÂN TAY'!B:B,B23,'CHẤM VÂN TAY'!I:I) -> 0 | F23: =SUMIF('CHẤM VÂN TAY'!B:B,B23,'CHẤM VÂN TAY'!J:J) -> 60 | G23: =SUMIF('CHẤM VÂN TAY'!B:B,B23,'CHẤM VÂN TAY'!K:K) -> 0 | H23: =SUMIF('CHẤM VÂN TAY'!$B:$B,B23,'CHẤM VÂN TAY'!$L:$L) -> 6 | I23: =SUMIF('CHẤM VÂN TAY'!B:B,B23,'CHẤM VÂN TAY'!M:M) -> 3
A24: 23 | B24: QUANG TRONG HAU | C24: VO TRUNG | D24: =sumif('CHẤM VÂN TAY'!B:B,B24,'CHẤM VÂN TAY'!H:H) -> 0 | E24: =SUMIF('CHẤM VÂN TAY'!B:B,B24,'CHẤM VÂN TAY'!I:I) -> 0 | F24: =SUMIF('CHẤM VÂN TAY'!B:B,B24,'CHẤM VÂN TAY'!J:J) -> 57 | G24: =SUMIF('CHẤM VÂN TAY'!B:B,B24,'CHẤM VÂN TAY'!K:K) -> 0 | H24: =SUMIF('CHẤM VÂN TAY'!$B:$B,B24,'CHẤM VÂN TAY'!$L:$L) -> 3 | I24: =SUMIF('CHẤM VÂN TAY'!B:B,B24,'CHẤM VÂN TAY'!M:M) -> 1
